<mujocoinclude model="winch">

  <!-- <extension> -->
  <!--   <plugin plugin="mujoco.elasticity.cable"/> -->
  <!-- </extension> -->
  <!---->
  <body name="winch" pos="0 0 0.026">
    <joint name="winch"/>
    <geom type="cylinder" size="0.02 0.02"/>
    <geom type="cylinder" size="0.04 0.002" pos="0 0 -0.022"/>
    <body name="B0" pos="0 0 -0.022" euler="0 -0.034 -1.6018">
      <inertial mass="0.01" diaginertia="0.0001 0.0001 0.0001" pos="0 0 0"/>
      <joint type="ball"/>
      <composite prefix="actuated" type="cable" curve="s" count="100 1 1"
                  size="0.432 .015 1" offset="0 0 0" initial="ball">
          <joint kind="main" damping="0.15" armature="0.01"/>
          <geom type="capsule" size=".001" rgba="0 0 1 1"/>
      </composite>
    </body>        
  </body>
  <!-- <actuator> -->
  <!--   <velocity name="winch" joint="winch" kv="200" ctrllimited="true" ctrlrange="-10 10"/> -->
  <!-- </actuator> -->
</mujocoinclude>
